<?xml version="1.0" encoding="utf-8"?>
<sdf version='1.6'>
  <model name='mobile_robot'>
    <link name='base_link'>
      <pose frame=''>0 0 0 0 -0 0</pose>
      <inertial>
        <pose frame=''>0.016345 0.001099 0.082159 0 -0 0</pose>
        <mass>0.506053</mass>
        <inertia>
          <ixx>0.00147019</ixx>
          <ixy>-0.000231366</ixy>
          <ixz>9.60475e-05</ixz>
          <iyy>0.00196655</iyy>
          <iyz>0.000203418</iyz>
          <izz>0.00109362</izz>
        </inertia>
      </inertial>
      <collision name='base_link_collision'>
        <pose frame=''>0 0 0 0 -0 0</pose>
        <geometry>
          <mesh>
            <scale>1 1 1</scale>
            <uri>model://mobile_robot/meshes/base_link.STL</uri>
          </mesh>
        </geometry>
      </collision>
      <collision name='base_link_fixed_joint_lump__cam_holder_collision_1'>
        <pose frame=''>-0.0295 -0.0225 0.1305 1.5708 -0 1.5708</pose>
        <geometry>
          <mesh>
            <scale>1 1 1</scale>
            <uri>model://mobile_robot/meshes/cam_holder.STL</uri>
          </mesh>
        </geometry>
      </collision>
      <collision name='base_link_fixed_joint_lump__lidar_collision_2'>
        <pose frame=''>0.0625 0.0175 0.0785 -1.5708 -0 -1.5708</pose>
        <geometry>
          <mesh>
            <scale>1 1 1</scale>
            <uri>model://mobile_robot/meshes/lidar.STL</uri>
          </mesh>
        </geometry>
      </collision>
      <collision name='base_link_fixed_joint_lump__motors_collision_3'>
        <pose frame=''>-0.0175 -0.0425 0.0985 1.5708 0 -1.5708</pose>
        <geometry>
          <mesh>
            <scale>1 1 1</scale>
            <uri>model://mobile_robot/meshes/motors.STL</uri>
          </mesh>
        </geometry>
      </collision>
      <visual name='base_link_visual'>
        <pose frame=''>0 0 0 0 -0 0</pose>
        <geometry>
          <mesh>
            <scale>1 1 1</scale>
            <uri>model://mobile_robot/meshes/base_link.STL</uri>
          </mesh>
        </geometry>
        <material>
          <ambient>0.7 0.1 0.1 1</ambient>
          <diffuse>0.7 0.1 0.1 1</diffuse>
          <specular>0 0 0 0</specular>
          <emissive>0 0 0 1</emissive>
        </material>
      </visual>
      <visual name='base_link_fixed_joint_lump__cam_holder_visual_1'>
        <pose frame=''>-0.0295 -0.0225 0.1305 1.5708 -0 1.5708</pose>
        <geometry>
          <mesh>
            <scale>1 1 1</scale>
            <uri>model://mobile_robot/meshes/cam_holder.STL</uri>
          </mesh>
        </geometry>
        <material>
          <ambient>0.4 0.2 0 1</ambient>
          <diffuse>0.4 0.2 0 1</diffuse>
          <specular>0 0 0 0</specular>
          <emissive>0 0 0 1</emissive>
        </material>
      </visual>
      <visual name='base_link_fixed_joint_lump__lidar_visual_2'>
        <pose frame=''>0.0625 0.0175 0.0785 -1.5708 -0 -1.5708</pose>
        <geometry>
          <mesh>
            <scale>1 1 1</scale>
            <uri>model://mobile_robot/meshes/lidar.STL</uri>
          </mesh>
        </geometry>
        <material>
          <ambient>0.3 0.3 0.3 1</ambient>
          <diffuse>0.3 0.3 0.3 1</diffuse>
          <specular>0 0 0 0</specular>
          <emissive>0 0 0 1</emissive>
        </material>
      </visual>
      <visual name='base_link_fixed_joint_lump__motors_visual_3'>
        <pose frame=''>-0.0175 -0.0425 0.0985 1.5708 0 -1.5708</pose>
        <geometry>
          <mesh>
            <scale>1 1 1</scale>
            <uri>model://mobile_robot/meshes/motors.STL</uri>
          </mesh>
        </geometry>
        <material>
          <ambient>0.4 0.4 0.4 1</ambient>
          <diffuse>0.4 0.4 0.4 1</diffuse>
          <specular>0 0 0 0</specular>
          <emissive>0 0 0 1</emissive>
        </material>
      </visual>
    </link>
    <link name='front_camera'>
      <pose frame=''>0.0255 0 0.188 0 0.2 0</pose>
      <inertial>
        <pose frame=''>0.01766 -0.022303 -8.9e-05 0 -0 0</pose>
        <mass>0.035961</mass>
        <inertia>
          <ixx>1.593e-05</ixx>
          <ixy>-6.2483e-08</ixy>
          <ixz>-2.5912e-09</ixz>
          <iyy>3.5917e-06</iyy>
          <iyz>3.141e-10</iyz>
          <izz>1.5415e-05</izz>
        </inertia>
      </inertial>
      <collision name='camera_collision'>
        <pose frame=''>0 0 0 0 -0 0</pose>
        <geometry>
          <mesh>
            <scale>1 1 1</scale>
            <uri>model://mobile_robot/meshes/camera.STL</uri>
          </mesh>
        </geometry>
      </collision>
      <visual name='camera_visual'>
        <pose frame=''>0 0 0 0 -0 0</pose>
        <geometry>
          <mesh>
            <scale>1 1 1</scale>
            <uri>model://mobile_robot/meshes/camera.STL</uri>
          </mesh>
        </geometry>
        <material>
          <ambient>0.3 0.3 0.3 1</ambient>
          <diffuse>0.3 0.3 0.3 1</diffuse>
          <specular>0 0 0 0</specular>
          <emissive>0 0 0 1</emissive>
        </material>
      </visual>
      <sensor name='camera' type='camera'>
        <update_rate>30</update_rate>
        <camera name='head'>
          <horizontal_fov>1.39626</horizontal_fov>
          <image>
            <width>800</width>
            <height>800</height>
            <format>R8G8B8</format>
          </image>
          <clip>
            <near>0.02</near>
            <far>300</far>
          </clip>
          <noise>
            <type>gaussian</type>
            <mean>0</mean>
            <stddev>0.007</stddev>
          </noise>
        </camera>
        <plugin name='camera_controller' filename='libgazebo_ros_camera.so'>
          <alwaysOn>true</alwaysOn>
          <updateRate>0.0</updateRate>
          <cameraName>camera</cameraName>
          <imageTopicName>image_raw</imageTopicName>
          <cameraInfoTopicName>camera_info</cameraInfoTopicName>
          <frameName>base_link</frameName>
          <hackBaseline>0.07</hackBaseline>
          <distortionK1>0.0</distortionK1>
          <distortionK2>0.0</distortionK2>
          <distortionK3>0.0</distortionK3>
          <distortionT1>0.0</distortionT1>
          <distortionT2>0.0</distortionT2>
        </plugin>
      </sensor>
    </link>
    <joint name='front_camera' type='revolute'>
      <child>front_camera</child>
      <parent>base_link</parent>
      <axis>
        <xyz>0 -1 0</xyz>
        <limit>
          <lower>0</lower>
          <upper>0</upper>
          <effort>0</effort>
          <velocity>0</velocity>
        </limit>
        <dynamics>
          <spring_reference>0</spring_reference>
          <spring_stiffness>0</spring_stiffness>
        </dynamics>
        <use_parent_model_frame>1</use_parent_model_frame>
      </axis>
    </joint>
    <link name='left_front_wheel'>
      <pose frame=''>0.035 0.0645 0.036 0 -0 0</pose>
      <inertial>
        <pose frame=''>0 0.01 -0 0 -0 0</pose>
        <mass>0.035123</mass>
        <inertia>
          <ixx>1.46931e-05</ixx>
          <ixy>2.29262e-21</ixy>
          <ixz>-3.92044e-22</ixz>
          <iyy>2.78576e-05</iyy>
          <iyz>-7.93526e-25</iyz>
          <izz>1.46931e-05</izz>
        </inertia>
      </inertial>
      <collision name='left_front_wheel_collision'>
        <pose frame=''>0 0 0 0 -0 0</pose>
        <geometry>
          <mesh>
            <scale>1 1 1</scale>
            <uri>model://mobile_robot/meshes/left_front_wheel.STL</uri>
          </mesh>
        </geometry>
      </collision>
      <visual name='left_front_wheel_visual'>
        <pose frame=''>0 0 0 0 -0 0</pose>
        <geometry>
          <mesh>
            <scale>1 1 1</scale>
            <uri>model://mobile_robot/meshes/left_front_wheel.STL</uri>
          </mesh>
        </geometry>
        <material>
          <ambient>0.2 0.2 0.2 1</ambient>
          <diffuse>0.2 0.2 0.2 1</diffuse>
          <specular>0 0 0 0</specular>
          <emissive>0 0 0 1</emissive>
        </material>
      </visual>
    </link>
    <joint name='left_front_wheel' type='revolute'>
      <child>left_front_wheel</child>
      <parent>base_link</parent>
      <axis>
        <xyz>0 1 0</xyz>
        <limit>
          <lower>-1e+16</lower>
          <upper>1e+16</upper>
        </limit>
        <dynamics>
          <spring_reference>0</spring_reference>
          <spring_stiffness>0</spring_stiffness>
        </dynamics>
        <use_parent_model_frame>1</use_parent_model_frame>
      </axis>
    </joint>
    <link name='left_rear_wheel'>
      <pose frame=''>-0.05 0.0645 0.036 0 -0 0</pose>
      <inertial>
        <pose frame=''>0 0.01 0 0 -0 0</pose>
        <mass>0.035123</mass>
        <inertia>
          <ixx>1.4693e-05</ixx>
          <ixy>1.1418e-21</ixy>
          <ixz>-3.9204e-22</ixz>
          <iyy>2.7858e-05</iyy>
          <iyz>-1.4418e-24</iyz>
          <izz>1.4693e-05</izz>
        </inertia>
      </inertial>
      <collision name='left_rear_wheel_collision'>
        <pose frame=''>0 0 0 0 -0 0</pose>
        <geometry>
          <mesh>
            <scale>1 1 1</scale>
            <uri>model://mobile_robot/meshes/left_rear_wheel.STL</uri>
          </mesh>
        </geometry>
      </collision>
      <visual name='left_rear_wheel_visual'>
        <pose frame=''>0 0 0 0 -0 0</pose>
        <geometry>
          <mesh>
            <scale>1 1 1</scale>
            <uri>model://mobile_robot/meshes/left_rear_wheel.STL</uri>
          </mesh>
        </geometry>
        <material>
          <ambient>0.2 0.2 0.2 1</ambient>
          <diffuse>0.2 0.2 0.2 1</diffuse>
          <specular>0 0 0 0</specular>
          <emissive>0 0 0 1</emissive>
        </material>
      </visual>
    </link>
    <joint name='left_rear_wheel' type='revolute'>
      <child>left_rear_wheel</child>
      <parent>base_link</parent>
      <axis>
        <xyz>0 1 0</xyz>
        <limit>
          <lower>-1e+16</lower>
          <upper>1e+16</upper>
        </limit>
        <dynamics>
          <spring_reference>0</spring_reference>
          <spring_stiffness>0</spring_stiffness>
        </dynamics>
        <use_parent_model_frame>1</use_parent_model_frame>
      </axis>
    </joint>
    <link name='right_front_wheel'>
      <pose frame=''>0.035 -0.0645 0.036 0 -0 0</pose>
      <inertial>
        <pose frame=''>0 -0.01 -0 0 -0 0</pose>
        <mass>0.035123</mass>
        <inertia>
          <ixx>1.46931e-05</ixx>
          <ixy>1.9903e-21</ixy>
          <ixz>-3.92044e-22</ixz>
          <iyy>2.78576e-05</iyy>
          <iyz>-2.48265e-25</iyz>
          <izz>1.46931e-05</izz>
        </inertia>
      </inertial>
      <collision name='right_front_wheel_collision'>
        <pose frame=''>0 0 0 0 -0 0</pose>
        <geometry>
          <mesh>
            <scale>1 1 1</scale>
            <uri>model://mobile_robot/meshes/right_front_wheel.STL</uri>
          </mesh>
        </geometry>
      </collision>
      <visual name='right_front_wheel_visual'>
        <pose frame=''>0 0 0 0 -0 0</pose>
        <geometry>
          <mesh>
            <scale>1 1 1</scale>
            <uri>model://mobile_robot/meshes/right_front_wheel.STL</uri>
          </mesh>
        </geometry>
        <material>
          <ambient>0.2 0.2 0.2 1</ambient>
          <diffuse>0.2 0.2 0.2 1</diffuse>
          <specular>0 0 0 0</specular>
          <emissive>0 0 0 1</emissive>
        </material>
      </visual>
    </link>
    <joint name='right_front_wheel' type='revolute'>
      <child>right_front_wheel</child>
      <parent>base_link</parent>
      <axis>
        <xyz>0 1 0</xyz>
        <limit>
          <lower>-1e+16</lower>
          <upper>1e+16</upper>
        </limit>
        <dynamics>
          <spring_reference>0</spring_reference>
          <spring_stiffness>0</spring_stiffness>
        </dynamics>
        <use_parent_model_frame>1</use_parent_model_frame>
      </axis>
    </joint>
    <link name='right_rear_wheel'>
      <pose frame=''>-0.05 -0.0645 0.036 0 -0 0</pose>
      <inertial>
        <pose frame=''>0 -0.01 0 0 -0 0</pose>
        <mass>0.035123</mass>
        <inertia>
          <ixx>1.4693e-05</ixx>
          <ixy>1.1418e-21</ixy>
          <ixz>-3.9204e-22</ixz>
          <iyy>2.7858e-05</iyy>
          <iyz>-1.4418e-24</iyz>
          <izz>1.4693e-05</izz>
        </inertia>
      </inertial>
      <collision name='right_rear_wheel_collision'>
        <pose frame=''>0 0 0 0 -0 0</pose>
        <geometry>
          <mesh>
            <scale>1 1 1</scale>
            <uri>model://mobile_robot/meshes/right_rear_wheel.STL</uri>
          </mesh>
        </geometry>
      </collision>
      <visual name='right_rear_wheel_visual'>
        <pose frame=''>0 0 0 0 -0 0</pose>
        <geometry>
          <mesh>
            <scale>1 1 1</scale>
            <uri>model://mobile_robot/meshes/right_rear_wheel.STL</uri>
          </mesh>
        </geometry>
        <material>
          <ambient>0.2 0.2 0.2 1</ambient>
          <diffuse>0.2 0.2 0.2 1</diffuse>
          <specular>0 0 0 0</specular>
          <emissive>0 0 0 1</emissive>
        </material>
      </visual>
    </link>
    <joint name='right_rear_wheel' type='revolute'>
      <child>right_rear_wheel</child>
      <parent>base_link</parent>
      <axis>
        <xyz>0 1 0</xyz>
        <limit>
          <lower>-1e+16</lower>
          <upper>1e+16</upper>
        </limit>
        <dynamics>
          <spring_reference>0</spring_reference>
          <spring_stiffness>0</spring_stiffness>
        </dynamics>
        <use_parent_model_frame>1</use_parent_model_frame>
      </axis>
    </joint>
    <plugin name='skid_steer_drive_controller' filename='libgazebo_ros_skid_steer_drive.so'>
      <updateRate>100.0</updateRate>
      <robotNamespace>/</robotNamespace>
      <leftFrontJoint>left_front_wheel</leftFrontJoint>
      <rightFrontJoint>right_front_wheel</rightFrontJoint>
      <leftRearJoint>left_rear_wheel</leftRearJoint>
      <rightRearJoint>right_rear_wheel</rightRearJoint>
      <wheelSeparation>0.129</wheelSeparation>
      <wheelDiameter>0.07</wheelDiameter>
      <robotBaseFrame>base_link</robotBaseFrame>
      <torque>20</torque>
      <topicName>cmd_vel</topicName>
      <broadcastTF>false</broadcastTF>
    </plugin>
  </model>
</sdf>
